Workbook

Sheet capacity
A1: Section | B1: Make | C1: Existing Number | E1: Capacity | F1: U/M | G1: Additional | H1: Cycle time(minute) | I1: Product | J1: Units/hours
A3: Cop winding-CT | B3: Alidhra | C3: 42 | D3: spindles
A4: Cop winding-TFO | C4: 42 | D4: spindles
A5: Compound twisting | B5: Alidhra | C5: 2 | D5: Machines
C6: 144 | D6: Take-up Spindles per machines
C7: 288 | D7: Total spindles
A8: TFO-2 PLY | B8: Aakash Engineering | C8: 1 | D8: machine
C9: 120 | D9: Take-up Spindles per machines
A10: TFO-2 PLY | C10: 1
C11: 80 | D11: Take-up Spindles per machines
A12: Filament soft package winder | B12: JOVIAN | C12: 18 | D12: Positions
A14: Spun soft package winder | B14: PEASS | C14: 48 | D14: Positions
A16: Dyeing laboratory
A17: package dyeing-200gram | C17: 2 | D17: Machines
A18: 600 gram | C18: 2 | D18: Machines
A19: 1 package | C19: 1 | D19: Machines
A20: 2 packages | C20: 2 | D20: Machines
A22: Dyeing Production
A23: package dyeing-5 p | B23: Fongs | C23: 2 | D23: Machines
A24: 15 p | B24: Weavetex | C24: 2 | D24: Machines
A25: 20 p | B25: Weavetex | C25: 2 | D25: Machines
A26: 30p | B26: Weavetex | C26: 1 | D26: Machines
A27: 48p | B27: Weavetex | C27: 1 | D27: Machines
A29: Hydro | B29: Unbranded | C29: 1 | D29: Machine
C30: 36 | D30: Positions
A31: RF Dryer | B31: Monga Strayfield | C31: 1 | D31: Machine
A33: Heat -Stretching- 100 mm godget | B33: Kim Textile | C33: 1 | D33: Machine
C34: 16 | D34: Positions | E34: 300 | F34: kg/day
A35: Heat -Stretching- 130 mm godget | B35: Kim Textile | C35: 1 | D35: Machine
B36: Kim Textile | C36: 16 | D36: Positions | E36: 300 | F36: kg/day
A38: Spun Cone winding | B38: Chang-li | C38: 20 | D38: Spindles | E38: 1944 | F38: Cones/day | H38: 17 | I38: ROXX GOLD | J38: 120
A42: Spun Tube winding | B42: Chang-li | C42: 30 | D42: Spindles | E42: 5020 | F42: Tubes/day | H42: =800/500*60+23 -> 119 | I42: ROXX POLY 800M | J42: =E42/24 -> 209.16667
E43: 9758 | F43: Tubes/day | H43: =180/500*60+23 -> 44.6 | I43: ROXX POLY 180M | J43: =E43/24 -> 406.58333
E44: 1534 | F44: Tubes/day | H44: =135/500*60+23 -> 39.2 | I44: ROXX-135M | J44: =E44/24 -> 63.916667
A46: Y-cone winding- 6 inch | B46: Chang-li | C46: 12 | D46: Spindles(1 U/spindle)
A47: Y-cone winding- 4 inch BF | B47: Chang-li | C47: 4 | D47: Spindles(2 U/spindle)
A48: Y-cone winding- 4 inch MF | B48: Chang-li | C48: 4 | D48: Spindles(2 U/spindle)
A49: Y-cone winding- 3.25 inch | B49: Chang-li | C49: 4 | D49: Spindles(2 U/spindle)
A50: Y-cone winding- 2 inch | B50: UTM | C50: 4 | D50: Spindles(3 U/spindle)
A52: Y-cone winding- 4 inch BF | B52: Reshmi | C52: 2 | D52: Spindles(1 U/spindle)
...

Sheet Cycle time-Filaments
A1: SR | B1: Brand Name | C1: Tkt | D1: Tex size | E1: Ply | F1: FG code | G1: Subs | H1: Length/ Wt. per unit | I1: U/M | J1: Make up | K1: Speed-mpm | L1: Theo cycle time-Minute | M1: No. of units/spindle | N1: Units/hour/spindle | O1: Theo Units/21 hours/spindle | P1: Efficiency | Q1: Actual units/21 hours/spindle | R1: Actual cycle time-minute | S1: No. of spindles | T1: Total capacity-actual | U1: PENDING PO | V1: TOTAL DAYS OF TAKE WINDING | W1: TOTAL CYCLE TIME NEEDED(MIN) | X1: Available minute
A2: 1 | B2: COMFO PLUS 60 | C2: 1 | D2: 50 | E2: 2 | F2: 2201 | G2: CFP | H2: 10000 | I2: m | J2: 4 in KS BF | K2: 700 | L2: =H2*1.005/K2+3 -> 17.357143 | M2: 1 | N2: =60/L2*M2 -> 3.4567901 | O2: =N2*22.5 -> 77.777778 | P2: 0.8 | Q2: =O2*P2 -> 62.222222 | R2: =L2/P2 -> 21.696429 | S2: 2 | T2: =Q2*S2 -> 124.44444 | U2: =VLOOKUP(F2,'PENDING PO'!A12:B87,2,0) -> 0 | V2: =U2/T2 -> 0 | W2: =U2*R2 -> 0 | X2: =M2*S2*21*60 -> 2520
A3: 2 | B3: COMFO 60 | C3: 2 | D3: 50 | E3: 2 | F3: 2202 | G3: CFP | H3: 2000 | I3: m | J3: 3.25 in KS | K3: 700 | L3: =H3*1.005/K3+0.5 -> 3.3714286 | M3: 1 | N3: =60/L3*M3 -> 17.79661 | O3: =N3*22.5 -> 400.42373 | P3: 0.85 | Q3: =O3*P3 -> 340.36017 | R3: =L3/P3 -> 3.9663866 | S3: 4 | T3: =Q3*S3 -> 1361.4407 | U3: =VLOOKUP(F3,'PENDING PO'!A13:B88,2,0) -> 30 | V3: =U3/T3 -> 0.022035481 | W3: =U3*R3 -> 118.9916
A4: 3 | B4: COMFO PLUS 60 | C4: 3 | D4: 50 | E4: 2 | F4: 2203 | G4: CFP-1 kg | H4: 17900 | I4: m | J4: 6 in KS BF | K4: 600 | L4: =H4*1.005/K4+3 -> 32.9825 | M4: 1 | N4: =60/L4*M4 -> 1.8191465 | O4: =N4*21 -> 38.202077 | P4: 0.85 | Q4: =O4*P4 -> 32.471765 | R4: =L4/P4 -> 38.802941 | S4: 12 | T4: =Q4*S4 -> 389.66118 | U4: =VLOOKUP(F4,'PENDING PO'!A15:B89,2,0) -> 0 | V4: =U4/T4 -> 0 | W4: =U4*R4 -> 0 | X4: =M4*S4*20*60 -> 14400
A5: 4 | B5: 1881 | C5: 4 | D5: 34.833333 | F5: 2204 | G5: 150*2 PLY CFP-8 gpd-950gr | H5: 24400 | I5: m | J5: 6 in KS BF | K5: 500 | L5: =H5*1.005/K5+3 -> 52.044 | M5: 1 | N5: =60/L5*M5 -> 1.1528706 | O5: =N5*21 -> 24.210284 | P5: 0.85 | Q5: =O5*P5 -> 20.578741 | R5: =L5/P5 -> 61.228235 | S5: 12 | T5: =Q5*S5 -> 246.94489 | U5: =VLOOKUP(F5,'PENDING PO'!A16:B92,2,0) -> 5 | V5: =U5/T5 -> 0.020247432 | W5: =U5*R5 -> 306.14118
A6: 5 | B6: 1887 | C6: 5 | D6: 48.766667 | F6: 2205 | G6: 210*2 PLY CFP-8 gpd-950 gr | H6: 17430 | I6: m | J6: 6 in KS BF | K6: 500 | L6: =H6*1.005/K6+3 -> 38.0343 | M6: 1 | N6: =60/L6*M6 -> 1.5775234 | O6: =N6*21 -> 33.127992 | P6: 0.85 | Q6: =O6*P6 -> 28.158794 | R6: =L6/P6 -> 44.746235 | S6: 12 | T6: =Q6*S6 -> 337.90552 | U6: =VLOOKUP(F6,'PENDING PO'!A17:B93,2,0) -> 0 | V6: =U6/T6 -> 0 | W6: =U6*R6 -> 0
A7: 6 | B7: 2209 | C7: 6 | D7: 48.766667 | F7: 2206 | G7: 210*2 PLY CFP-580 gr | H7: 10800 | I7: m | J7: 4 in KS BF | K7: 700 | L7: 24.708 | M7: 1 | N7: 4.8567266 | O7: =N7*21 -> 101.99126 | P7: 0.85 | Q7: =O7*P7 -> 86.692569 | R7: 32.944 | S7: 2 | T7: 291.40359 | U7: =VLOOKUP(F7,'PENDING PO'!A18:B94,2,0) -> 0 | V7: =U7/T7 -> 0 | W7: =U7*R7 -> 0
A8: 7 | B8: COMFO PRIDE | C8: 7 | D8: 27 | E8: 2 | F8: 2207 | G8: 120/2 Cf Polyester premium fror embroidery | H8: 5000 | I8: m | J8: 3.25 in KS | K8: 700 | L8: =H8*1.005/K8+0.5 -> 7.6785714 | M8: 1 | N8: =60/L8*M8 -> 7.8139535 | O8: =N8*22.5 -> 175.81395 | P8: 0.85 | Q8: =O8*P8 -> 149.44186 | R8: =L8/P8 -> 9.0336134 | S8: 4 | T8: =Q8*S8 -> 597.76744 | U8: =VLOOKUP(F8,'PENDING PO'!A19:B95,2,0) -> 0 | V8: =U8/T8 -> 0 | W8: =U8*R8 -> 0
A9: 8 | B9: COMFO 80 | C9: 8 | D9: 30 | E9: 2 | F9: 2208 | G9: 150/2 CFP | H9: 5000 | I9: m | J9: 4 in KS MF | K9: 700 | L9: =H9*1.005/K9+0.5 -> 7.6785714 | M9: 1 | N9: =60/L9*M9 -> 7.8139535 | O9: =N9*22.5 -> 175.81395 | P9: 0.85 | Q9: =O9*P9 -> 149.44186 | R9: =L9/P9 -> 9.0336134 | S9: 4 | T9: =Q9*S9 -> 597.76744 | U9: =VLOOKUP(F9,'PENDING PO'!A20:B96,2,0) -> 0 | V9: =U9/T9 -> 0 | W9: =U9*R9 -> 0
A10: 9 | B10: COMFO 80 | C10: 9 | D10: 80 | E10: 2 | F10: 2209 | G10: 150/2 CFP | H10: 15000 | I10: m | J10: 4 in KS BF | K10: 700 | L10: =H10*1.005/K10+3 -> 24.535714 | M10: 2 | N10: =60/L10*M10 -> 4.8908297 | O10: =N10*21 -> 102.70742 | P10: 0.85 | Q10: =O10*P10 -> 87.30131 | R10: =L10/P10 -> 28.865546 | S10: 2 | T10: =Q10*S10 -> 174.60262 | U10: =VLOOKUP(F10,'PENDING PO'!A21:B97,2,0) -> 0 | V10: =U10/T10 -> 0 | W10: =U10*R10 -> 0
A11: 10 | B11: COMFO 80 | C11: 10 | D11: 35 | E11: 2 | F11: 2210 | G11: 150/2 CFP | H11: 15000 | I11: m | J11: 6 in KS BF | K11: 600 | L11: =H11*1.005/K11+3 -> 28.125 | M11: 1 | N11: =60/L11*M11 -> 2.1333333 | O11: =N11*21 -> 44.8 | P11: 0.85 | Q11: =O11*P11 -> 38.08 | R11: =L11/P11 -> 33.088235 | S11: 12 | T11: =Q11*S11 -> 456.96 | U11: =VLOOKUP(F11,'PENDING PO'!A22:B98,2,0) -> 4280 | V11: =U11/T11 -> 9.3662465 | W11: =U11*R11 -> 141617.65
A12: 11 | B12: COMFO 60 SUPER | C12: 11 | D12: 50 | E12: 2 | F12: 2211 | G12: 210*2 PLY CFP-7.5 GPD-1 kG | H12: 45490 | J12: 6 in KS BF | K12: 600 | L12: =H12*1.005/K12+3 -> 79.19575 | M12: 1 | N12: =60/L12*M12 -> 0.75761641 | O12: =N12*21 -> 15.909945 | P12: 0.85 | Q12: =O12*P12 -> 13.523453 | R12: =L12/P12 -> 93.171471 | S12: 12 | T12: =Q12*S12 -> 162.28144 | U12: =VLOOKUP(F12,'PENDING PO'!A22:B98,2,0) -> 0 | V12: =U12/T12 -> 0 | W12: =U12*R12 -> 0
A13: 12 | B13: COMFO PLUS | C13: 12 | D13: 70 | E13: 3 | F13: 2301 | G13: CFP | H13: 12000 | I13: m | J13: 6 in KS BF | K13: 600 | L13: =H13*1.005/K13+3 -> 23.1 | M13: 1 | N13: =60/L13*M13 -> 2.5974026 | O13: =N13*21 -> 54.545455 | P13: 0.8 | Q13: =O13*P13 -> 43.636364 | R13: =L13/P13 -> 28.875 | S13: 12 | T13: =Q13*S13 -> 523.63636 | U13: =VLOOKUP(F13,'PENDING PO'!A23:B99,2,0) -> 0 | V13: =U13/T13 -> 0 | W13: =U13*R13 -> 0
A14: 13 | B14: COMFO PREMIUM | C14: 13 | D14: 70 | E14: 3 | F14: 2302 | G14: CFP | H14: 7000 | I14: m | J14: 4 in KS BF | K14: 700 | L14: =H14*1.005/K14+3 -> 13.05 | M14: 1 | N14: =60/L14*M14 -> 4.5977011 | O14: =N14*22.5 -> 103.44828 | P14: 0.75 | Q14: =O14*P14 -> 77.586207 | R14: =L14/P14 -> 17.4 | S14: 2 | T14: =Q14*S14 -> 155.17241 | U14: =VLOOKUP(F14,'PENDING PO'!A24:B100,2,0) -> 12378 | V14: =U14/T14 -> 79.769333 | W14: =U14*R14 -> 215377.2
A15: 14 | B15: COMFO COOL | C15: 14 | D15: 70 | E15: 3 | F15: 2303 | G15: CFP | H15: 1500 | I15: m | J15: 3.25 in KS | K15: 700 | L15: =H15*1.005/K15+0.5 -> 2.6535714 | M15: 1 | N15: =60/L15*M15 -> 22.611036 | O15: =N15*22.5 -> 508.74832 | P15: 0.85 | Q15: =O15*P15 -> 432.43607 | R15: =L15/P15 -> 3.1218487 | S15: 4 | T15: =Q15*S15 -> 1729.7443 | U15: =VLOOKUP(F15,'PENDING PO'!A27:B101,2,0) -> 8619 | V15: =U15/T15 -> 4.9828175 | W15: =U15*R15 -> 26907.214
A16: 15 | B16: COMFO STAR | C16: 15 | D16: 70 | E16: 3 | F16: 2304 | G16: CFP | H16: 500 | I16: m | J16: 2 in KS | K16: 180 | L16: =H16*1.005/K16+3 -> 5.7916667 | M16: 3 | N16: =60/L16*M16 -> 31.079137 | O16: =N16*20 -> 621.58273 | P16: 0.65 | Q16: =O16*P16 -> 404.02878 | R16: =L16/P16 -> 8.9102564 | S16: 4 | T16: =Q16*S16 -> 1616.1151 | U16: =VLOOKUP(F16,'PENDING PO'!A28:B101,2,0) -> 0 | V16: =U16/T16 -> 0 | W16: =U16*R16 -> 0
A17: 16 | B17: COMFO PLUS | C17: 16 | D17: 70 | E17: 3 | F17: 2305 | G17: CFP | H17: 10000 | I17: m | J17: 6 in KS BF | K17: 600 | L17: =H17*1.005/K17+3 -> 19.75 | M17: 1 | N17: =60/L17*M17 -> 3.0379747 | O17: =N17*21 -> 63.797468 | P17: 0.75 | Q17: =O17*P17 -> 47.848101 | R17: =L17/P17 -> 26.333333 | S17: 12 | T17: =Q17*S17 -> 574.17722 | U17: =VLOOKUP(F17,'PENDING PO'!A29:B101,2,0) -> 2079 | V17: =U17/T17 -> 3.6208333 | W17: =U17*R17 -> 54747
A18: 17 | B18: COMFO 30 | C18: 17 | D18: 90 | E18: 3 | F18: 2306 | G18: CFP | H18: 1500 | I18: m | J18: 3.25 in KS | K18: 700 | L18: =H18*1.005/K18+0.5 -> 2.6535714 | M18: 1 | N18: =60/L18*M18 -> 22.611036 | O18: =N18*22.5 -> 508.74832 | P18: 0.85 | Q18: =O18*P18 -> 432.43607 | R18: =L18/P18 -> 3.1218487 | S18: 4 | T18: =Q18*S18 -> 1729.7443 | U18: =VLOOKUP(F18,'PENDING PO'!A30:B101,2,0) -> 0 | V18: =U18/T18 -> 0 | W18: =U18*R18 -> 0
A19: 18 | B19: COMFO PLUS | C19: 18 | D19: 70 | E19: 3 | F19: 2307 | G19: CFP-1kg | H19: 11470 | I19: m | J19: 6 in KS BF | K19: 600 | L19: =H19*1.005/K19+3 -> 22.21225 | M19: 1 | N19: =60/L19*M19 -> 2.7012122 | O19: =N19*21 -> 56.725456 | P19: 0.8 | Q19: =O19*P19 -> 45.380364 | R19: =L19/P19 -> 27.765312 | S19: 12 | T19: =Q19*S19 -> 544.56437 | U19: =VLOOKUP(F19,'PENDING PO'!A31:B101,2,0) -> 0 | V19: =U19/T19 -> 0 | W19: =U19*R19 -> 0
A20: 19 | B20: COMFO PLUS 20 | C20: 19 | D20: 135 | E20: 3 | F20: 2310 | G20: CFP | H20: 5000 | I20: m | J20: 6 in KS BF | K20: 600 | L20: =H20*1.005/K20+3 -> 11.375 | M20: 1 | N20: =60/L20*M20 -> 5.2747253 | O20: =N20*21 -> 110.76923 | P20: 0.7 | Q20: =O20*P20 -> 77.538462 | R20: =L20/P20 -> 16.25 | S20: 12 | T20: =Q20*S20 -> 930.46154 | U20: =VLOOKUP(F20,'PENDING PO'!A32:B101,2,0) -> 0 | V20: =U20/T20 -> 0 | W20: =U20*R20 -> 0
A21: 20 | B21: COMFO 20 | C21: 20 | D21: 135 | E21: 3 | F21: 2311 | G21: CFP | H21: 1000 | I21: m | J21: 4 in KS MF | K21: 700 | L21: =H21*1.005/K21+3 -> 4.4357143 | M21: 1 | N21: =60/L21*M21 -> 13.52657 | O21: =N21*22.5 -> 304.34783 | P21: 0.85 | Q21: =O21*P21 -> 258.69565 | R21: =L21/P21 -> 5.2184874 | S21: 4 | T21: =Q21*S21 -> 1034.7826 | U21: =VLOOKUP(F21,'PENDING PO'!A33:B101,2,0) -> 49 | V21: =U21/T21 -> 0.047352941 | W21: =U21*R21 -> 255.70588
A22: 21 | B22: 1106 | C22: 21 | D22: 73.15 | F22: 2313 | G22: 210*3 PLY CFP 8gpd | H22: 3000 | I22: m | J22: 4 in KS MF | K22: 700 | L22: =H22*1.005/K22+3 -> 7.3071429 | M22: 1 | N22: =60/L22*M22 -> 8.2111437 | O22: =N22*22.5 -> 184.75073 | P22: 0.85 | Q22: =O22*P22 -> 157.03812 | R22: =L22/P22 -> 8.5966387 | S22: 4 | T22: =Q22*S22 -> 628.15249 | U22: =VLOOKUP(F22,'PENDING PO'!A34:B101,2,0) -> 4280 | V22: =U22/T22 -> 6.8136321 | W22: =U22*R22 -> 36793.613
A23: 22 | B23: 1107 | C23: 22 | D23: 155.078 | F23: 2314 | G23: 420*3 ply CFP(8gpd) | H23: 1500 | I23: m | J23: 4 in KS MF | K23: 700 | L23: =H23*1.005/K23+3 -> 5.1535714 | M23: 1 | N23: =60/L23*M23 -> 11.642412 | O23: =N23*22.5 -> 261.95426 | P23: 0.85 | Q23: =O23*P23 -> 222.66112 | R23: =L23/P23 -> 6.0630252 | S23: 4 | T23: =Q23*S23 -> 890.64449 | U23: =VLOOKUP(F23,'PENDING PO'!A35:B101,2,0) -> 1356 | V23: =U23/T23 -> 1.522493 | W23: =U23*R23 -> 8221.4622
A24: 23 | B24: 2853 | C24: 23 | D24: 73.15 | F24: 2315 | G24: 210*3 PLY CFP 7.5gpd | H24: 3000 | I24: m | J24: 4 in KS MF | K24: 700 | L24: =H24*1.005/K24+3 -> 7.3071429 | M24: 1 | N24: =60/L24*M24 -> 8.2111437 | O24: =N24*22.5 -> 184.75073 | P24: 0.85 | Q24: =O24*P24 -> 157.03812 | R24: =L24/P24 -> 8.5966387 | S24: 4 | T24: =Q24*S24 -> 628.15249 | U24: =VLOOKUP(F24,'PENDING PO'!A36:B101,2,0) -> 12378 | V24: =U24/T24 -> 19.705406 | W24: =U24*R24 -> 106409.19
A25: 24 | B25: 2851 | C25: 24 | D25: 146.3 | F25: 2316 | G25: 420*3 PLY CFP 7.5gpd | H25: 1500 | I25: m | J25: 4 in KS MF | K25: 700 | L25: =H25*1.005/K25+3 -> 5.1535714 | M25: 1 | N25: =60/L25*M25 -> 11.642412 | O25: =N25*22.5 -> 261.95426 | P25: 0.85 | Q25: =O25*P25 -> 222.66112 | R25: =L25/P25 -> 6.0630252 | S25: 4 | T25: =Q25*S25 -> 890.64449 | U25: =VLOOKUP(F25,'PENDING PO'!A37:B101,2,0) -> 8619 | V25: =U25/T25 -> 9.6772619 | W25: =U25*R25 -> 52257.214
A26: 25 | B26: 1380 | C26: 25 | D26: 292.6 | F26: 2317 | G26: 840*3 PLY CFP 8gpd | H26: 1000 | I26: m | J26: 4 in KS MF | K26: 600 | L26: =H26*1.005/K26+3 -> 4.675 | M26: 1 | N26: =60/L26*M26 -> 12.834225 | O26: =N26*22.5 -> 288.77005 | P26: 0.85 | Q26: =O26*P26 -> 245.45455 | R26: =L26/P26 -> 5.5 | S26: 4 | T26: =Q26*S26 -> 981.81818 | U26: =VLOOKUP(F26,'PENDING PO'!A38:B101,2,0) -> 2079 | V26: =U26/T26 -> 2.1175 | W26: =U26*R26 -> 11434.5
A27: 26 | B27: 1377 | C27: 26 | D27: 174.16667 | F27: 2318 | G27: 500*3 PLY CFP 7.5gpd | H27: 1500 | I27: m | J27: 4 in KS MF | K27: 600 | L27: =H27*1.005/K27+3 -> 5.5125 | M27: 1 | N27: =60/L27*M27 -> 10.884354 | O27: =N27*22.5 -> 244.89796 | P27: 0.85 | Q27: =O27*P27 -> 208.16327 | R27: =L27/P27 -> 6.4852941 | S27: 4 | T27: =Q27*S27 -> 832.65306 | U27: =VLOOKUP(F27,'PENDING PO'!A39:B101,2,0) -> 49 | V27: =U27/T27 -> 0.058848039 | W27: =U27*R27 -> 317.77941
A28: 27 | B28: 2855 | C28: 27 | D28: 73.15 | F28: 2319 | G28: 210*3 PLY CFP-8 gpd | H28: 6500 | I28: m | J28: 4 in KS BF | K28: 700 | L28: =H28*1.005/K28+3 -> 12.332143 | M28: 1 | N28: =60/L28*M28 -> 4.8653345 | O28: =N28*21 -> 102.17202 | P28: 0.75 | Q28: =O28*P28 -> 76.629018 | R28: =L28/P28 -> 16.442857 | S28: 2 | T28: =Q28*S28 -> 153.25804 | U28: =VLOOKUP(F28,'PENDING PO'!A40:B101,2,0) -> 0 | V28: =U28/T28 -> 0 | W28: =U28*R28 -> 0
A29: 28 | B29: COMFO 20(for denim) | C29: 28 | D29: 135 | E29: 3 | F29: 2320 | G29: 420*3 PLY CFP 7.5gpd | H29: 1000 | I29: m | J29: 4 in KS MF | K29: 700 | L29: =H29*1.005/K29+3 -> 4.4357143 | M29: 1 | N29: =60/L29*M29 -> 13.52657 | O29: =N29*22.5 -> 304.34783 | P29: 0.85 | Q29: =O29*P29 -> 258.69565 | R29: =L29/P29 -> 5.2184874 | S29: 4 | T29: =Q29*S29 -> 1034.7826 | U29: =VLOOKUP(F29,'PENDING PO'!A41:B102,2,0) -> 0 | V29: =U29/T29 -> 0 | W29: =U29*R29 -> 0
A30: 29 | B30: 2852 | C30: 29 | D30: 87.083333 | F30: 2321 | G30: CFP 8gpd | H30: 1500 | I30: m | J30: 4 in KS MF | K30: 700 | L30: =H30*1.005/K30+3 -> 5.1535714 | M30: 1 | N30: =60/L30*M30 -> 11.642412 | O30: =N30*22.5 -> 261.95426 | P30: 0.85 | Q30: =O30*P30 -> 222.66112 | R30: =L30/P30 -> 6.0630252 | S30: 4 | T30: =Q30*S30 -> 890.64449 | U30: =VLOOKUP(F30,'PENDING PO'!A42:B103,2,0) -> 7310 | V30: =U30/T30 -> 8.2075397 | W30: =U30*R30 -> 44320.714
A31: 30 | B31: 2854 | C31: 30 | D31: 52.25 | F31: 2322 | G31: CFP 8gpd | H31: 3000 | I31: m | J31: 4 in KS MF | K31: 700 | L31: =H31*1.005/K31+3 -> 7.3071429 | M31: 1 | N31: =60/L31*M31 -> 8.2111437 | O31: =N31*22.5 -> 184.75073 | P31: 0.85 | Q31: =O31*P31 -> 157.03812 | R31: =L31/P31 -> 8.5966387 | S31: 4 | T31: =Q31*S31 -> 628.15249 | U31: =VLOOKUP(F31,'PENDING PO'!A43:B104,2,0) -> 1356 | V31: =U31/T31 -> 2.1587115 | W31: =U31*R31 -> 11657.042
A32: 31 | B32: COMFO 20 | C32: 31 | D32: 135 | E32: 3 | F32: 2323 | G32: CFP 8gpd | H32: 1500 | I32: m | J32: 4 in KS MF | K32: 700 | L32: =H32*1.005/K32+3 -> 5.1535714 | M32: 1 | N32: =60/L32*M32 -> 11.642412 | O32: =N32*21 -> 244.49064 | P32: 0.85 | Q32: =O32*P32 -> 207.81705 | R32: =L32/P32 -> 6.0630252 | S32: 4 | T32: =Q32*S32 -> 831.26819 | U32: =VLOOKUP(F32,'PENDING PO'!A44:B105,2,0) -> 0 | V32: =U32/T32 -> 0 | W32: =U32*R32 -> 0
A33: 32 | B33: COMFO 40 | C33: 32 | D33: 70 | E33: 3 | F33: 2324 | G33: CFP 8gpd | H33: 3000 | I33: m | J33: 4 in KS MF | K33: 700 | L33: =H33*1.005/K33+3 -> 7.3071429 | M33: 1 | N33: =60/L33*M33 -> 8.2111437 | O33: =N33*21 -> 172.43402 | P33: 0.85 | Q33: =O33*P33 -> 146.56891 | R33: =L33/P33 -> 8.5966387 | S33: 4 | T33: =Q33*S33 -> 586.27566 | U33: =VLOOKUP(F33,'PENDING PO'!A45:B106,2,0) -> 0 | V33: =U33/T33 -> 0 | W33: =U33*R33 -> 0
A34: 33 | B34: COMFO 8 | C34: 33 | D34: 350 | E34: 3 | F34: 2325 | G34: CFP | H34: 500 | I34: m | J34: 4 in KS MF | K34: 500 | L34: =H34*1.005/K34+3 -> 4.005 | M34: 1 | N34: =60/L34*M34 -> 14.981273 | O34: =N34*21 -> 314.60674 | P34: 0.85 | Q34: =O34*P34 -> 267.41573 | R34: =L34/P34 -> 4.7117647 | S34: 4 | T34: =Q34*S34 -> 1069.6629 | U34: =VLOOKUP(F34,'PENDING PO'!A46:B107,2,0) -> 0 | V34: =U34/T34 -> 0 | W34: =U34*R34 -> 0
A35: 34 | B35: COMFO 40 | C35: 34 | D35: 70 | E35: 3 | F35: 2326 | G35: CFP | H35: 1500 | I35: m | J35: 3.25 in KS | K35: 700 | L35: =H35*1.005/K35+3 -> 5.1535714 | M35: 1 | N35: =60/L35*M35 -> 11.642412 | O35: =N35*21 -> 244.49064 | P35: 0.85 | Q35: =O35*P35 -> 207.81705 | R35: =L35/P35 -> 6.0630252 | S35: 4 | T35: =Q35*S35 -> 831.26819 | U35: =VLOOKUP(F35,'PENDING PO'!A47:B108,2,0) -> 0 | V35: =U35/T35 -> 0 | W35: =U35*R35 -> 0
A36: 35 | B36: TUFF 60 | C36: 35 | D36: 45 | E36: 2 | F36: 3201 | G36: CFN-6 | H36: 1000 | I36: m | J36: 3.25 in KS | K36: 700 | L36: =H36*1.005/K36+0.5 -> 1.9357143 | M36: 1 | N36: =60/L36*M36 -> 30.99631 | O36: =N36*22.5 -> 697.41697 | P36: 0.85 | Q36: =O36*P36 -> 592.80443 | R36: =L36/P36 -> 2.2773109 | S36: 4 | T36: =Q36*S36 -> 2371.2177 | U36: =VLOOKUP(F36,'PENDING PO'!A48:B109,2,0) -> 208 | V36: =U36/T36 -> 0.087718643 | W36: =U36*R36 -> 473.68067
A37: 36 | B37: TUFF PREMIUM 60 | C37: 36 | D37: 45 | E37: 2 | F37: 3202 | G37: CFN-6 | H37: 2000 | I37: m | J37: 3.25 in KS | K37: 700 | L37: =H37*1.005/K37+0.5 -> 3.3714286 | M37: 1 | N37: =60/L37*M37 -> 17.79661 | O37: =N37*22.5 -> 400.42373 | P37: 0.85 | Q37: =O37*P37 -> 340.36017 | R37: =L37/P37 -> 3.9663866 | S37: 4 | T37: =Q37*S37 -> 1361.4407 | U37: =VLOOKUP(F37,'PENDING PO'!A49:B110,2,0) -> 4243 | V37: =U37/T37 -> 3.1165515 | W37: =U37*R37 -> 16829.378
A38: 37 | B38: Tuff 60 | C38: 37 | D38: 50 | E38: 3 | F38: 3203 | G38: CFN-6 | H38: 500 | I38: m | J38: 2 in KS | K38: 180 | L38: =H38*1.005/K38+3 -> 5.7916667 | M38: 3 | N38: =60/L38*M38 -> 31.079137 | O38: =N38*20 -> 621.58273 | P38: 0.65 | Q38: =O38*P38 -> 404.02878 | R38: =L38/P38 -> 8.9102564 | S38: 4 | T38: =Q38*S38 -> 1616.1151 | U38: =VLOOKUP(F38,'PENDING PO'!A50:B111,2,0) -> 152 | V38: =U38/T38 -> 0.094052707 | W38: =U38*R38 -> 1354.359 | X38: =M38*S38*20*60 -> 14400
A39: 38 | B39: TUFF PREMIUM | C39: 38 | D39: 70 | E39: 3 | F39: 3301 | G39: CFN-6 | H39: 500 | I39: m | J39: 2 in KS | K39: 180 | L39: =H39*1.005/K39+3 -> 5.7916667 | M39: 3 | N39: =60/L39*M39 -> 31.079137 | O39: =N39*20 -> 621.58273 | P39: 0.65 | Q39: =O39*P39 -> 404.02878 | R39: =L39/P39 -> 8.9102564 | S39: 4 | T39: =Q39*S39 -> 1616.1151 | U39: =VLOOKUP(F39,'PENDING PO'!A51:B112,2,0) -> 6873 | V39: =U39/T39 -> 4.2527911 | W39: =U39*R39 -> 61240.192 | X39: =M39*S39*20*60 -> 14400
A40: 39 | B40: TUFF CLASSIC | C40: 39 | D40: 70 | E40: 3 | F40: 3302 | G40: CFN-6 | H40: 1500 | I40: m | J40: 3.25 in KS | K40: 700 | L40: =H40*1.005/K40+0.5 -> 2.6535714 | M40: 1 | N40: =60/L40*M40 -> 22.611036 | O40: =N40*22.5 -> 508.74832 | P40: 0.85 | Q40: =O40*P40 -> 432.43607 | R40: =L40/P40 -> 3.1218487 | S40: 4 | T40: =Q40*S40 -> 1729.7443 | U40: =VLOOKUP(F40,'PENDING PO'!A52:B113,2,0) -> 11203 | V40: =U40/T40 -> 6.4766799 | W40: =U40*R40 -> 34974.071
...

Sheet overall lead time
B3: OVERALL LEAD TIME PENDING ORDER CAPACITY
D4: =TODAY() -> 46237
B5: SR | C5: Make up | D5: TOTAL DAYS OF TAKE WINDING
B6: 1 | C6: 2 in KS | D6: ='Cycle time-Filaments'!V16+'Cycle time-Filaments'!V38+'Cycle time-Filaments'!V39 -> 4.3468438
B7: 2 | C7: 3.25 in KS | D7: ='Cycle time-Filaments'!V3+'Cycle time-Filaments'!V8+'Cycle time-Filaments'!V15+'Cycle time-Filaments'!V18+'Cycle time-Filaments'!V35+'Cycle time-Filaments'!V36+'Cycle time-Filaments'!V37+'Cycle time-Filaments'!V40+'Cycle time-Filaments'!V41+'Cycle time-Filaments'!V42+'Cycle time-Filaments'!V45+'Cycle time-Filaments'!V47+'Cycle time-Filaments'!V52+'Cycle time-Filaments'!V55 -> 14.697365
B8: 3 | C8: 4 in KS BF | D8: ='Cycle time-Filaments'!V2+'Cycle time-Filaments'!V7+'Cycle time-Filaments'!V10+'Cycle time-Filaments'!V14+'Cycle time-Filaments'!V28+'Cycle time-Filaments'!V57 -> 79.769333
B9: 4 | C9: 4 in KS MF | D9: ='Cycle time-Filaments'!V9+'Cycle time-Filaments'!V21+'Cycle time-Filaments'!V22+'Cycle time-Filaments'!V23+'Cycle time-Filaments'!V24+'Cycle time-Filaments'!V25+'Cycle time-Filaments'!V26+'Cycle time-Filaments'!V27+'Cycle time-Filaments'!V29+'Cycle time-Filaments'!V30+'Cycle time-Filaments'!V31+'Cycle time-Filaments'!V32+'Cycle time-Filaments'!V33+'Cycle time-Filaments'!V34+'Cycle time-Filaments'!V43+'Cycle time-Filaments'!V44+'Cycle time-Filaments'!V46+'Cycle time-Filaments'!V48+'Cycle time-Filaments'!V49+'Cycle time-Filaments'!V50+'Cycle time-Filaments'!V51+'Cycle time-Filaments'!V53+'Cycle time-Filaments'!V54+'Cycle time-Filaments'!V56 -> 51.000368
B10: 4 | C10: 6 in KS BF | D10: ='Cycle time-Filaments'!V4+'Cycle time-Filaments'!V5+'Cycle time-Filaments'!V6+'Cycle time-Filaments'!V11+'Cycle time-Filaments'!V12+'Cycle time-Filaments'!V13+'Cycle time-Filaments'!V17+'Cycle time-Filaments'!V19+'Cycle time-Filaments'!V20+'Cycle time-Filaments'!V58 -> 18.813719
B11: 5 | C11: 4 in V-Cone | D11: ='Cycle time SSP-TXP-PPC'!V28 -> 27.486947
B12: 6 | C12: Tube | D12: ='Cycle time TUBE)'!V10 -> 0

Sheet Cycle time SSP-TXP-PPC
A1: SR | B1: Brand Name | C1: Tkt | D1: Tex size | E1: Ply | F1: FG code | G1: Subs | H1: Length/ Wt. per unit | I1: U/M | J1: Make up | K1: Speed-mpm | L1: Theo cycle time-Minute | M1: No. of units/spindle | N1: Units/hour/spindle | O1: Theo Units/20 hours/spindle | P1: Efficiency | Q1: Actual units/21 hours/spindle | R1: Actual cycle time-minute | S1: No. of spindles | T1: Total capacity-actual | U1: PENDING PO | V1: TOTAL DAYS OF TAKE WINDING | W1: TOTAL CYCLE TIME NEEDED(MIN)
A2: 1 | B2: ROXX GOLD | C2: 60 | D2: 20 | E2: 2 | F2: 1201 | G2: SSP | H2: 10000 | I2: m | J2: 4 in Cone | K2: 600 | L2: =H2*1.005/K2+3 -> 19.75 | M2: 2 | N2: =60/L2*M2 -> 6.0759494 | O2: =N2*22 -> 133.67089 | P2: 0.8 | Q2: =O2*P2 -> 106.93671 | R2: =L2/P2 -> 24.6875 | S2: 30 | T2: =Q2*S2 -> 3208.1013 | U2: =VLOOKUP(F2,'PENDING PO'!A2:B89,2,0) -> 68254 | V2: =U2/T2 -> 21.275513 | W2: =U2*R2 -> 1685020.6 | Y2: =24*60 -> 1440
A3: 2 | B3: ROXX STAR | C3: 60 | D3: 20 | E3: 2 | F3: 1202 | G3: SSP-200 gram | H3: 9177 | I3: m | J3: 4 in Cone | K3: 600 | L3: =H3*1.005/K3+3 -> 18.371475 | M3: 2 | N3: =60/L3*M3 -> 6.5318653 | O3: =N3*22 -> 143.70104 | P3: 0.8 | Q3: =O3*P3 -> 114.96083 | R3: =L3/P3 -> 22.964344 | S3: 30 | T3: =Q3*S3 -> 3448.8249 | U3: =VLOOKUP(F3,'PENDING PO'!A3:B92,2,0) -> 16640 | V3: =U3/T3 -> 4.8248318 | W3: =U3*R3 -> 382126.68 | Y3: =Y2/19.75 -> 72.911392 | Z3: =Y3*2 -> 145.82278
A4: 3 | B4: ROXX 50 | C4: 50 | D4: 60 | E4: 2 | F4: 1203 | G4: SSP | H4: 2000 | I4: m | J4: 4 in Cone | K4: 500 | L4: =H4*1.005/K4+3 -> 7.02 | M4: 2 | N4: =60/L4*M4 -> 17.094017 | O4: =N4*22 -> 376.06838 | P4: 0.65 | Q4: =O4*P4 -> 244.44444 | R4: =L4/P4 -> 10.8 | S4: 30 | T4: =Q4*S4 -> 7333.3333 | U4: =VLOOKUP(F4,'PENDING PO'!A4:B93,2,0) -> 10 | V4: =U4/T4 -> 0.0013636364 | W4: =U4*R4 -> 108 | Z4: =Z3*30 -> 4374.6835
A5: 4 | B5: ROXX SILVER | C5: 60 | D5: 20 | E5: 2 | F5: 1208 | G5: SSP | H5: 5000 | I5: m | J5: 4 in Cone | K5: 600 | L5: =H5*1.005/K5+3 -> 11.375 | M5: 2 | N5: =60/L5*M5 -> 10.549451 | O5: =N5*22 -> 232.08791 | P5: 0.75 | Q5: =O5*P5 -> 174.06593 | R5: =L5/P5 -> 15.166667 | S5: 30 | T5: =Q5*S5 -> 5221.978 | U5: =VLOOKUP(F5,'PENDING PO'!A5:B94,2,0) -> 5487 | V5: =U5/T5 -> 1.0507513 | W5: =U5*R5 -> 83219.5 | Z5: =Z4/100*80 -> 3499.7468
A6: 5 | B6: ROXX GOLD(KIRAN) | C6: 60 | D6: 20 | E6: 2 | F6: 1210 | G6: SSP | H6: 10000 | I6: m | J6: 4 in Cone | K6: 600 | L6: =H6*1.005/K6+3 -> 19.75 | M6: 2 | N6: =60/L6*M6 -> 6.0759494 | O6: =N6*22 -> 133.67089 | P6: 0.8 | Q6: =O6*P6 -> 106.93671 | R6: =L6/P6 -> 24.6875 | S6: 30 | T6: =Q6*S6 -> 3208.1013 | U6: =VLOOKUP(F6,'PENDING PO'!A6:B94,2,0) -> 0 | V6: =U6/T6 -> 0 | W6: =U6*R6 -> 0 | Z6: =Z5/100*80 -> 2799.7975
A7: 6 | B7: ROXX GOLD(ZIGMA) | C7: 60 | D7: 20 | E7: 2 | F7: 1211 | G7: SSP | H7: 10000 | I7: m | J7: 4 in Cone | K7: 600 | L7: =H7*1.005/K7+3 -> 19.75 | M7: 2 | N7: =60/L7*M7 -> 6.0759494 | O7: =N7*22 -> 133.67089 | P7: 0.8 | Q7: =O7*P7 -> 106.93671 | R7: =L7/P7 -> 24.6875 | S7: 30 | T7: =Q7*S7 -> 3208.1013 | U7: =VLOOKUP(F7,'PENDING PO'!A6:B95,2,0) -> 845 | V7: =U7/T7 -> 0.26339568 | W7: =U7*R7 -> 20860.937
A8: 7 | B8: ROXX 30 | C8: 30 | D8: 90 | E8: 3 | F8: 1301 | G8: SSP | H8: 1500 | I8: m | J8: 4 in Cone | K8: 500 | L8: =H8*1.005/K8+3 -> 6.015 | M8: 2 | N8: =60/L8*M8 -> 19.950125 | O8: =N8*22 -> 438.90274 | P8: 0.6 | Q8: =O8*P8 -> 263.34165 | R8: =L8/P8 -> 10.025 | S8: 30 | T8: =Q8*S8 -> 7900.2494 | U8: =VLOOKUP(F8,'PENDING PO'!A7:B96,2,0) -> 0 | V8: =U8/T8 -> 0 | W8: =U8*R8 -> 0
A9: 8 | B9: ROXX EURO | C9: 100 | D9: 30 | E9: 3 | F9: 1303 | G9: SSP | H9: 5000 | I9: m | J9: 4 in Cone | K9: 600 | L9: =H9*1.005/K9+3 -> 11.375 | M9: 2 | N9: =60/L9*M9 -> 10.549451 | O9: =N9*22 -> 232.08791 | P9: 0.75 | Q9: =O9*P9 -> 174.06593 | R9: =L9/P9 -> 15.166667 | S9: 30 | T9: =Q9*S9 -> 5221.978 | U9: =VLOOKUP(F9,'PENDING PO'!A11:B97,2,0) -> 118 | V9: =U9/T9 -> 0.022596801 | W9: =U9*R9 -> 1789.6667
A10: 9 | B10: ROXX 20 | C10: 20 | D10: 125 | E10: 4 | F10: 1401 | G10: SSP | H10: 1500 | I10: m | J10: 4 in Cone | K10: 500 | L10: =H10*1.005/K10+3 -> 6.015 | M10: 2 | N10: =60/L10*M10 -> 19.950125 | O10: =N10*22 -> 438.90274 | P10: 0.6 | Q10: =O10*P10 -> 263.34165 | R10: =L10/P10 -> 10.025 | S10: 30 | T10: =Q10*S10 -> 7900.2494 | U10: =VLOOKUP(F10,'PENDING PO'!A12:B98,2,0) -> 0 | V10: =U10/T10 -> 0 | W10: =U10*R10 -> 0
A11: 10 | B11: ROXX CORE POLY | C11: 120 | D11: 24 | E11: 2 | F11: 4201 | G11: PPC | H11: 5000 | I11: m | J11: 4 in Cone | K11: 600 | L11: =H11*1.005/K11+3 -> 11.375 | M11: 2 | N11: =60/L11*M11 -> 10.549451 | O11: =N11*22 -> 232.08791 | P11: 0.75 | Q11: =O11*P11 -> 174.06593 | R11: =L11/P11 -> 15.166667 | S11: 30 | T11: =Q11*S11 -> 5221.978 | U11: =VLOOKUP(F11,'PENDING PO'!A13:B99,2,0) -> 0 | V11: =U11/T11 -> 0 | W11: =U11*R11 -> 0
A12: 11 | B12: ROXX CORE POLY | C12: 100 | D12: 30 | E12: 2 | F12: 4202 | G12: PPC | H12: 5000 | I12: m | J12: 4 in Cone | K12: 600 | L12: =H12*1.005/K12+3 -> 11.375 | M12: 2 | N12: =60/L12*M12 -> 10.549451 | O12: =N12*22 -> 232.08791 | P12: 0.75 | Q12: =O12*P12 -> 174.06593 | R12: =L12/P12 -> 15.166667 | S12: 30 | T12: =Q12*S12 -> 5221.978 | U12: =VLOOKUP(F12,'PENDING PO'!A15:B100,2,0) -> 0 | V12: =U12/T12 -> 0 | W12: =U12*R12 -> 0
A13: 12 | B13: ROXX CORE POLY | C13: 75 | D13: 40 | E13: 2 | F13: 4203 | G13: PPC | H13: 2000 | I13: m | J13: 4 in Cone | K13: 600 | L13: =H13*1.005/K13+3 -> 6.35 | M13: 2 | N13: =60/L13*M13 -> 18.897638 | O13: =N13*22 -> 415.74803 | P13: 0.65 | Q13: =O13*P13 -> 270.23622 | R13: =L13/P13 -> 9.7692308 | S13: 30 | T13: =Q13*S13 -> 8107.0866 | U13: =VLOOKUP(F13,'PENDING PO'!A16:B101,2,0) -> 0 | V13: =U13/T13 -> 0 | W13: =U13*R13 -> 0
A14: 13 | B14: ROXX CORE POLY | C14: 50 | D14: 60 | E14: 2 | F14: 4204 | G14: PPC | H14: 2000 | I14: m | J14: 4 in Cone | K14: 600 | L14: =H14*1.005/K14+3 -> 6.35 | M14: 2 | N14: =60/L14*M14 -> 18.897638 | O14: =N14*22 -> 415.74803 | P14: 0.65 | Q14: =O14*P14 -> 270.23622 | R14: =L14/P14 -> 9.7692308 | S14: 30 | T14: =Q14*S14 -> 8107.0866 | U14: =VLOOKUP(F14,'PENDING PO'!A17:B101,2,0) -> 300 | V14: =U14/T14 -> 0.037004662 | W14: =U14*R14 -> 2930.7692
A15: 14 | B15: ROXX CORE POLY | C15: 40 | D15: 80 | E15: 2 | F15: 4206 | G15: PPC | H15: 3000 | I15: m | J15: 4 in Cone | K15: 600 | L15: =H15*1.005/K15+3 -> 8.025 | M15: 2 | N15: =60/L15*M15 -> 14.953271 | O15: =N15*22 -> 328.97196 | P15: 0.7 | Q15: =O15*P15 -> 230.28037 | R15: =L15/P15 -> 11.464286 | S15: 30 | T15: =Q15*S15 -> 6908.4112 | U15: =VLOOKUP(F15,'PENDING PO'!A18:B101,2,0) -> 0 | V15: =U15/T15 -> 0 | W15: =U15*R15 -> 0
A16: 15 | B16: ROXX CORE POLY | C16: 25 | D16: 105 | E16: 2 | F16: 4207 | G16: PPC | H16: 1000 | I16: m | J16: 4 in Cone | K16: 500 | L16: =H16*1.005/K16+3 -> 5.01 | M16: 2 | N16: =60/L16*M16 -> 23.952096 | O16: =N16*22 -> 526.94611 | P16: 0.55 | Q16: =O16*P16 -> 289.82036 | R16: =L16/P16 -> 9.1090909 | S16: 30 | T16: =Q16*S16 -> 8694.6108 | U16: =VLOOKUP(F16,'PENDING PO'!A19:B101,2,0) -> 0 | V16: =U16/T16 -> 0 | W16: =U16*R16 -> 0
A17: 16 | B17: ROXX CORE POLY | C17: 75 | D17: 40 | E17: 2 | F17: 4208 | G17: PPC | H17: 5000 | I17: m | J17: 4 in Cone | K17: 500 | L17: =H17*1.005/K17+3 -> 13.05 | M17: 2 | N17: =60/L17*M17 -> 9.1954023 | O17: =N17*22 -> 202.29885 | P17: 0.75 | Q17: =O17*P17 -> 151.72414 | R17: =L17/P17 -> 17.4 | S17: 30 | T17: =Q17*S17 -> 4551.7241 | U17: =VLOOKUP(F17,'PENDING PO'!A20:B101,2,0) -> 0 | V17: =U17/T17 -> 0 | W17: =U17*R17 -> 0
A18: 17 | B18: ROXX CORE POLY | C18: 120 | D18: 24 | E18: 2 | F18: 4209 | G18: PPC(PREMIUM) | H18: 5000 | I18: m | J18: 4 in Cone | K18: 600 | L18: =H18*1.005/K18+3 -> 11.375 | M18: 2 | N18: =60/L18*M18 -> 10.549451 | O18: =N18*22 -> 232.08791 | P18: 0.75 | Q18: =O18*P18 -> 174.06593 | R18: =L18/P18 -> 15.166667 | S18: 30 | T18: =Q18*S18 -> 5221.978 | U18: =VLOOKUP(F18,'PENDING PO'!A21:B101,2,0) -> 0 | V18: =U18/T18 -> 0 | W18: =U18*R18 -> 0
A19: 18 | B19: ROXX CORE POLY | C19: 100 | D19: 30 | E19: 2 | F19: 4210 | G19: PPC(PREMIUM) | H19: 5000 | I19: m | J19: 4 in Cone | K19: 600 | L19: =H19*1.005/K19+3 -> 11.375 | M19: 2 | N19: =60/L19*M19 -> 10.549451 | O19: =N19*22 -> 232.08791 | P19: 0.75 | Q19: =O19*P19 -> 174.06593 | R19: =L19/P19 -> 15.166667 | S19: 30 | T19: =Q19*S19 -> 5221.978 | U19: =VLOOKUP(F19,'PENDING PO'!A22:B101,2,0) -> 0 | V19: =U19/T19 -> 0 | W19: =U19*R19 -> 0
A20: 19 | B20: ROXX CORE POLY | C20: 75 | D20: 40 | E20: 2 | F20: 4211 | G20: PPC(PREMIUM) | H20: 2000 | I20: m | J20: 4 in Cone | K20: 600 | L20: =H20*1.005/K20+3 -> 6.35 | M20: 2 | N20: =60/L20*M20 -> 18.897638 | O20: =N20*22 -> 415.74803 | P20: 0.75 | Q20: =O20*P20 -> 311.81102 | R20: =L20/P20 -> 8.4666667 | S20: 30 | T20: =Q20*S20 -> 9354.3307 | U20: =VLOOKUP(F20,'PENDING PO'!A23:B101,2,0) -> 0 | V20: =U20/T20 -> 0 | W20: =U20*R20 -> 0
A21: 20 | B21: ROXX CORE POLY | C21: 30 | D21: 90 | E21: 3 | F21: 4305 | G21: PPC | H21: 1500 | I21: m | J21: 4 in Cone | K21: 500 | L21: =H21*1.005/K21+3 -> 6.015 | M21: 2 | N21: =60/L21*M21 -> 19.950125 | O21: =N21*22 -> 438.90274 | P21: 0.6 | Q21: =O21*P21 -> 263.34165 | R21: =L21/P21 -> 10.025 | S21: 30 | T21: =Q21*S21 -> 7900.2494 | U21: =VLOOKUP(F21,'PENDING PO'!A24:B101,2,0) -> 0 | V21: =U21/T21 -> 0 | W21: =U21*R21 -> 0
A22: 21 | B22: COMFO TEX 150 | C22: 160 | D22: 17 | E22: 1 | F22: 7102 | G22: TEXTURED POLYESTER 150D/100TPM | H22: 5000 | I22: m | J22: 4 in Cone | K22: 600 | L22: =H22*1.005/K22+3 -> 11.375 | M22: 2 | N22: =60/L22*M22 -> 10.549451 | O22: =N22*22 -> 232.08791 | P22: 0.75 | Q22: =O22*P22 -> 174.06593 | R22: =L22/P22 -> 15.166667 | S22: 30 | T22: =Q22*S22 -> 5221.978 | U22: =VLOOKUP(F22,'PENDING PO'!A27:B101,2,0) -> 0 | V22: =U22/T22 -> 0 | W22: =U22*R22 -> 0
A23: 22 | B23: COMFO TEX 80 | C23: 80 | D23: 35 | E23: 1 | F23: 7103 | G23: TEXTURED POLYESTER 300D/100TPM | H23: 5000 | I23: m | J23: 4 in Cone | K23: 600 | L23: =H23*1.005/K23+3 -> 11.375 | M23: 2 | N23: =60/L23*M23 -> 10.549451 | O23: =N23*22 -> 232.08791 | P23: 0.75 | Q23: =O23*P23 -> 174.06593 | R23: =L23/P23 -> 15.166667 | S23: 30 | T23: =Q23*S23 -> 5221.978 | U23: =VLOOKUP(F23,'PENDING PO'!A28:B101,2,0) -> 60 | V23: =U23/T23 -> 0.011489899 | W23: =U23*R23 -> 910
A24: 23 | B24: ROXX SILKY | C24: 150 | D24: 18 | E24: 2 | F24: 7201 | G24: COMPACT POLYESTER | H24: 10000 | I24: m | J24: 4 in Cone | K24: 600 | L24: =H24*1.005/K24+3 -> 19.75 | M24: 2 | N24: =60/L24*M24 -> 6.0759494 | O24: =N24*22 -> 133.67089 | P24: 0.8 | Q24: =O24*P24 -> 106.93671 | R24: =L24/P24 -> 24.6875 | S24: 30 | T24: =Q24*S24 -> 3208.1013 | U24: =VLOOKUP(F24,'PENDING PO'!A29:B101,2,0) -> 0 | V24: =U24/T24 -> 0 | W24: =U24*R24 -> 0
A25: 24 | B25: ROXX SILKY 120 | C25: 120 | D25: 27 | E25: 3 | F25: 7301 | G25: COMPACT POLYESTER | H25: 5000 | I25: m | J25: 4 in Cone | K25: 600 | L25: =H25*1.005/K25+3 -> 11.375 | M25: 2 | N25: =60/L25*M25 -> 10.549451 | O25: =N25*22 -> 232.08791 | P25: 0.75 | Q25: =O25*P25 -> 174.06593 | R25: =L25/P25 -> 15.166667 | S25: 30 | T25: =Q25*S25 -> 5221.978 | U25: =VLOOKUP(F25,'PENDING PO'!A30:B102,2,0) -> 0 | V25: =U25/T25 -> 0 | W25: =U25*R25 -> 0
U28: =SUM(U2:U25) -> 91714 | V28: =SUM(V2:V25) -> 27.486947
W29: =SUM(W2:W24) -> 2176966.2
D30: Available time(minute) | W30: =20*2*20*60 -> 48000
D31: Requd day | W31: =W29/W30 -> 45.353462

Sheet PENDING PO
A1: ART | B1: PO | C1: Make up | D1: REMARKS
A2: 1201 | B2: =VLOOKUP(A2,[1]Sheet2!$A$3:$C$44,3,0) -> 68254 | D2: Cycle time SSP-TXP-PPC
A3: 1202 | B3: =VLOOKUP(A3,[1]Sheet2!$A$3:$C$44,3,0) -> 16640 | D3: Cycle time SSP-TXP-PPC
A4: 1203 | B4: =VLOOKUP(A4,[1]Sheet2!$A$3:$C$44,3,0) -> 10 | D4: Cycle time SSP-TXP-PPC
A5: 1206 | B5: =VLOOKUP(A5,[1]Sheet2!$A$3:$C$44,3,0) -> 0 | D5: Cycle time TUBE)
A6: 1207 | B6: =VLOOKUP(A6,[1]Sheet2!$A$3:$C$44,3,0) -> 0 | D6: Cycle time TUBE)
A7: 1208 | B7: =VLOOKUP(A7,[1]Sheet2!$A$3:$C$44,3,0) -> 5487 | D7: Cycle time SSP-TXP-PPC
A8: 1210 | D8: Cycle time SSP-TXP-PPC
A9: 1211 | B9: =VLOOKUP(A9,[1]Sheet2!$A$3:$C$44,3,0) -> 845 | D9: Cycle time SSP-TXP-PPC
A10: 1215 | D10: Cycle time TUBE)
A11: 1301 | D11: Cycle time SSP-TXP-PPC
A12: 1302 | B12: =VLOOKUP(A12,[1]Sheet2!$A$3:$C$44,3,0) -> 0 | D12: Cycle time TUBE)
A13: 1303 | B13: =VLOOKUP(A13,[1]Sheet2!$A$3:$C$44,3,0) -> 118 | D13: Cycle time SSP-TXP-PPC
A14: 1304 | D14: Cycle time TUBE)
A15: 1401 | D15: Cycle time SSP-TXP-PPC
A16: 2201 | D16: Cycle time-Filaments
A17: 2202 | B17: =VLOOKUP(A17,[1]Sheet2!$A$3:$C$44,3,0) -> 30 | D17: Cycle time-Filaments
A18: 2203 | D18: Cycle time-Filaments
A19: 2204 | B19: =VLOOKUP(A19,[1]Sheet2!$A$3:$C$44,3,0) -> 5 | D19: Cycle time-Filaments
A20: 2205 | B20: =VLOOKUP(A20,[1]Sheet2!$A$3:$C$44,3,0) -> 0 | D20: Cycle time-Filaments
A21: 2206 | D21: Cycle time-Filaments
A22: 2207 | D22: Cycle time-Filaments
A23: 2208 | D23: Cycle time-Filaments
A24: 2209 | D24: Cycle time-Filaments
A25: 2210 | B25: =VLOOKUP(A25,[1]Sheet2!$A$3:$C$44,3,0) -> 4280 | D25: Cycle time-Filaments
A26: 2211 | D26: Cycle time-Filaments
A27: 2301 | D27: Cycle time-Filaments
A28: 2302 | B28: =VLOOKUP(A28,[1]Sheet2!$A$3:$C$44,3,0) -> 12378 | D28: Cycle time-Filaments
A29: 2303 | B29: =VLOOKUP(A29,[1]Sheet2!$A$3:$C$44,3,0) -> 8619 | D29: Cycle time-Filaments
A30: 2304 | D30: Cycle time-Filaments
A31: 2305 | B31: =VLOOKUP(A31,[1]Sheet2!$A$3:$C$44,3,0) -> 2079 | D31: Cycle time-Filaments
A32: 2306 | D32: Cycle time-Filaments
A33: 2307 | D33: Cycle time-Filaments
A34: 2310 | D34: Cycle time-Filaments
A35: 2311 | B35: =VLOOKUP(A35,[1]Sheet2!$A$3:$C$44,3,0) -> 49 | D35: Cycle time-Filaments
A36: 2313 | B36: =VLOOKUP(A36,[1]Sheet2!$A$3:$C$44,3,0) -> 4280 | D36: Cycle time-Filaments
A37: 2314 | B37: =VLOOKUP(A37,[1]Sheet2!$A$3:$C$44,3,0) -> 1356 | D37: Cycle time-Filaments
A38: 2315 | B38: =VLOOKUP(A38,[1]Sheet2!$A$3:$C$44,3,0) -> 12378 | D38: Cycle time-Filaments
A39: 2316 | B39: =VLOOKUP(A39,[1]Sheet2!$A$3:$C$44,3,0) -> 8619 | D39: Cycle time-Filaments
A40: 2317 | B40: =VLOOKUP(A40,[1]Sheet2!$A$3:$C$44,3,0) -> 2079 | D40: Cycle time-Filaments
...

Sheet Routing 
A1: PUNP | B1: Raw Mat | C1: Twisting | D1: Autoclave | E1: Soft Pkg | F1: Autoclave | G1: Soft Pkg | H1: Dyeing | I1: Stretching | J1: Winding | K1: Packing
A2: Filament-Unbonded | B2: Single yarn | C2: Twisting | D2: Autoclave | E2: Soft Pkg | H2: Dyeing | I2: Stretching+lube | J2: Winding+Lube | K2: Packing | L2: For NW Autoclave & no soft pkg, no dyeing,
A3: Nylon6 | B3: Raw Mat | C3: Twisting | D3: Autoclave | E3: Soft Pkg | H3: Dyeing | I3: Stretching+lube | J3: Winding+Lube | K3: Packing | L3: For NW Autoclave & no soft pkg, no dyeing,
A4: Nylon6 | B4: Raw Mat | C4: Twisting | D4: Autoclave | E4: Soft Pkg | H4: Dyeing | I4: Stretching+lube | J4: Winding+Lube | K4: Packing | L4: For NW Autoclave & no soft pkg, no dyeing,
A5: Nylon6 | B5: Raw Mat | C5: Twisting | D5: Autoclave | E5: Soft Pkg | H5: Dyeing | I5: Stretching+lube | J5: Winding+Lube | K5: Packing | L5: For NW Autoclave & no soft pkg, no dyeing,
A6: CFP | B6: Raw Mat | C6: Twisting | D6: Autoclave | E6: Soft Pkg | H6: Dyeing | I6: Stretching+lube | J6: Winding+Lube | K6: Packing | L6: For NW Autoclave & no soft pkg, no dyeing,
A7: Nylon 66 bonded | B7: Raw Mat | C7: Twisting | E7: Soft Pkg | F7: Autoclave | G7: Soft Pkg | H7: Dyeing | I7: Stretching+lube | J7: Winding | K7: Packing | L7: For NW Autoclave no dyeing,
A8: 4007 | H8: Dyeing | J8: Winding | K8: Packing | L8: For NW Autoclave & no soft pkg, no dyeing,Glazing
A9: 5009 | B9: Raw Mat | C9: Twisting | E9: Soft Pkg | H9: Dyeing | J9: Oiling+Winding | K9: Packing | L9: For NW Mat Autoclave, no Soft Pkg & no Dyeing
A10: Spun Polyester-dyed | B10: Raw Mat | E10: Soft Pkg | H10: Dyeing | J10: Oiling+Winding | K10: Packing | L10: For NW Mat Autoclave, no Soft Pkg & no Dyeing
A11: Poly Poly core spun | B11: Raw Mat | H11: Dyeing | J11: Oiling+Winding | K11: Packing | L11: For NW Mat Autoclave, no Soft Pkg & no Dyeing
A12: 5096 | B12: Raw Mat | E12: Soft Pkg | H12: Dyeing | J12: Oiling+Winding | K12: Packing | L12: For NW Mat Autoclave, no Soft Pkg & no Dyeing
A13: 5708 | B13: Raw Mat | I13: Stretching+lube | J13: Winding | K13: Packing
A14: 5147 | B14: Raw Mat | C14: Twisting | E14: Soft Pkg | H14: Dyeing | J14: Oiling+Winding | K14: Packing | L14: For NW Mat Autoclave, no Soft Pkg & no Dyeing

Sheet Cycle time TUBE)
A1: SR | B1: Brand Name | C1: Tkt | D1: Tex size | E1: Ply | F1: FG code | G1: Subs | H1: Length/ Wt. per unit | I1: U/M | J1: Make up | K1: Speed-mpm | L1: Theo cycle time-Minute | M1: No. of units/spindle | N1: Units/hour/spindle | O1: Theo Units/21 hours/spindle | P1: Efficiency | Q1: Actual units/21 hours/spindle | R1: Actual cycle time-minute | S1: No. of spindles | T1: Total capacity-actual boxes | U1: PENDING PO | V1: TOTAL DAYS OF TAKE WINDING | W1: TOTAL CYCLE TIME NEEDED(MIN)
A2: 1 | B2: ROXX POLY | C2: 60 | D2: 20 | E2: 2 | F2: 1207 | G2: SSP | H2: 800 | I2: m | J2: Tube(10 tube/box) | K2: 500 | L2: =H2*1.005/K2+0.4 -> 2.008 | M2: 1 | N2: =60/L2*M2 -> 29.880478 | O2: =N2*22 -> 657.37052 | P2: 0.7 | Q2: =O2*P2 -> 460.15936 | R2: =L2/P2 -> 2.8685714 | S2: 30 | T2: =Q2*S2/10 -> 1380.4781 | U2: =VLOOKUP(F2,'PENDING PO'!A2:B89,2,0) -> 0 | V2: =U2/T2 -> 0 | W2: =U2*R2 -> 0
A3: 2 | B3: ROXX POLY | C3: 60 | D3: 20 | E3: 2 | F3: 1206 | G3: SSP | H3: 180 | I3: m | J3: Tube(20 tubes/box) | K3: 400 | L3: =H3*1.005/K3+0.4 -> 0.85225 | M3: 1 | N3: =60/L3*M3 -> 70.401877 | O3: =N3*22 -> 1548.8413 | P3: 0.6 | Q3: =O3*P3 -> 929.30478 | R3: =L3/P3 -> 1.4204167 | S3: 30 | T3: =Q3*S3/20 -> 1393.9572 | U3: =VLOOKUP(F3,'PENDING PO'!A3:B92,2,0) -> 0 | V3: =U3/T3 -> 0 | W3: =U3*R3 -> 0
A4: 3 | B4: ROXX DIAMOND | C4: 80 | D4: 30 | E4: 3 | F4: 1302 | G4: SSP | H4: 135 | I4: m | J4: Tube(20 tubes/box) | K4: 400 | L4: =H4*1.005/K4+0.4 -> 0.7391875 | M4: 1 | N4: =60/L4*M4 -> 81.170204 | O4: =N4*22 -> 1785.7445 | P4: 0.55 | Q4: =O4*P4 -> 982.15947 | R4: =L4/P4 -> 1.3439773 | S4: 30 | T4: =Q4*S4/20 -> 1473.2392 | U4: =VLOOKUP(F4,'PENDING PO'!A4:B93,2,0) -> 0 | V4: =U4/T4 -> 0 | W4: =U4*R4 -> 0
A5: 4 | B5: ROXX POLY 120 | C5: 120 | D5: 25 | E5: 2 | F5: 1215 | G5: SSP | H5: 2000 | I5: m | J5: Tube(10 tubes/box) | K5: 600 | L5: =H5*1.005/K5+0.4 -> 3.75 | M5: 1 | N5: =60/L5*M5 -> 16 | O5: =N5*22 -> 352 | P5: 0.7 | Q5: =O5*P5 -> 246.4 | R5: =L5/P5 -> 5.3571429 | S5: 30 | T5: =Q5*S5/10 -> 739.2 | U5: =VLOOKUP(F5,'PENDING PO'!A5:B94,2,0) -> 0 | V5: =U5/T5 -> 0 | W5: =U5*R5 -> 0
A6: 5 | B6: ROXX EURO | C6: 100 | D6: 30 | E6: 3 | F6: 1304 | G6: SSP | H6: 1000 | I6: m | J6: Tube(10 tubes/box) | K6: 500 | L6: =H6*1.005/K6+0.4 -> 2.41 | M6: 1 | N6: =60/L6*M6 -> 24.896266 | O6: =N6*22 -> 547.71784 | P6: 0.7 | Q6: =O6*P6 -> 383.40249 | R6: =L6/P6 -> 3.4428571 | S6: 30 | T6: =Q6*S6/10 -> 1150.2075 | U6: =VLOOKUP(F6,'PENDING PO'!A6:B95,2,0) -> 0 | V6: =U6/T6 -> 0 | W6: =U6*R6 -> 0
A7: 6 | B7: ROXX CORE POLY | C7: 75 | D7: 40 | E7: 2 | F7: 4213 | G7: PPC | H7: 800 | I7: m | J7: Tube(10 tubes/box) | K7: 500 | L7: =H7*1.005/K7+0.4 -> 2.008 | M7: 1 | N7: =60/L7*M7 -> 29.880478 | O7: =N7*22 -> 657.37052 | P7: 0.7 | Q7: =O7*P7 -> 460.15936 | R7: =L7/P7 -> 2.8685714 | S7: 30 | T7: =Q7*S7/10 -> 1380.4781 | U7: =VLOOKUP(F7,'PENDING PO'!A7:B96,2,0) -> 0 | V7: =U7/T7 -> 0 | W7: =U7*R7 -> 0
A8: 7 | B8: ROXX CORE POLY | C8: 100 | D8: 30 | E8: 2 | F8: 4212 | G8: PPC | H8: 1000 | I8: m | J8: Tube(10 tubes/box) | K8: 500 | L8: =H8*1.005/K8+0.4 -> 2.41 | M8: 1 | N8: =60/L8*M8 -> 24.896266 | O8: =N8*22 -> 547.71784 | P8: 0.7 | Q8: =O8*P8 -> 383.40249 | R8: =L8/P8 -> 3.4428571 | S8: 30 | T8: =Q8*S8/10 -> 1150.2075 | U8: =VLOOKUP(F8,'PENDING PO'!A9:B97,2,0) -> 0 | V8: =U8/T8 -> 0 | W8: =U8*R8 -> 0
U10: =SUM(U2:U4) -> 0 | V10: =SUM(V2:V8) -> 0 | W10: =SUM(W2:W4) -> 0
D11: Available time(minute) | W11: =30*1*21*60 -> 37800
D12: Requd day | W12: =W10/W11 -> 0
