Workbook

Sheet Art_starts_with_1
A1: Article | B1: Color | C1: Last_date_of_Odr | D1: actual_tot_in_Qty | E1: actual_tot_wt_in_KG | F1: Total_Frequency | G1: No_of_parties | H1: Parties
A2: 1201 | B2: BLACK | C2: 46258 | D2: 3890 | E2: 785.78 | F2: 12 | G2: 2 | H2: CHIRAG CREATIONS, ZIGMA
A3: 1201 | B3: BW | C3: 46158 | D3: 1130 | E3: 228.26 | F3: 4 | G3: 1 | H3: ZIGMA
A4: 1201 | B4: D10002 | C4: 46271 | D4: 65 | E4: 13.13 | F4: 1 | G4: 1 | H4: ZIGMA
A5: 1201 | B5: D10003 | C5: 46271 | D5: 530 | E5: 107.06 | F5: 5 | G5: 1 | H5: ZIGMA
A6: 1201 | B6: D10005 | C6: 46270 | D6: 130 | E6: 26.26 | F6: 2 | G6: 1 | H6: ZIGMA
A7: 1201 | B7: D10006 | C7: 46193 | D7: 100 | E7: 20.2 | F7: 2 | G7: 1 | H7: ZIGMA
A8: 1201 | B8: D10007 | C8: 46192 | D8: 120 | E8: 24.24 | F8: 2 | G8: 1 | H8: ZIGMA
A9: 1201 | B9: D10008 | C9: 46195 | D9: 100 | E9: 20.2 | F9: 1 | G9: 1 | H9: ZIGMA
A10: 1201 | B10: D10011 | C10: 46233 | D10: 255 | E10: 51.51 | F10: 6 | G10: 2 | H10: K.K. HOSIERY MATERIAL STORE, ZIGMA
A11: 1201 | B11: D10033 | C11: 46164 | D11: 190 | E11: 38.38 | F11: 1 | G11: 1 | H11: ZIGMA
A12: 1201 | B12: D10035 | C12: 46265 | D12: 70 | E12: 14.14 | F12: 3 | G12: 1 | H12: ZIGMA
A13: 1201 | B13: D10036 | C13: 46271 | D13: 190 | E13: 38.38 | F13: 4 | G13: 1 | H13: ZIGMA
... A1650: 1401 | B1650: S01350 | C1650: 46223 | D1650: 0 | E1650: 0 | F1650: 1 | G1650: 1 | H1650: FANTAIL

Sheet 2-60 PENDINGORDERTOPLAN.rpt
A1: Order No. | B1: DO No. | C1: DO Date. | D1: Party Name. | E1: Shade Name | F1: D.O. Qty | G1: Plan Qty | H1: Issue Qty | I1: Cancel Qty | J1: Dispatch Qty | K1: Bal PlanQty | L1: no of batch | M1: avg monthly Movement quantity
A2: ST00445/26 | B2: ST0044502N | C2: 46271 | D2: KIRAN INDUSTRIES PVT LTD (STICH DIV SALES) | E2: D10002 | F2: 13.91 | I2: 0 | J2: 0 | K2: 13.91 | L2: 1 | M2: =VLOOKUP($E2,'only2-60'!$A$2:$H$848,5,0) -> #N/A | P2: =VLOOKUP(E2,'Take it'!$A$4:$D$771,2,0) -> 13.13
A3: ST00445/26 | B3: ST0044501N | C3: 46271 | D3: KIRAN INDUSTRIES PVT LTD (STICH DIV SALES) | E3: D10003 | F3: 13.91 | I3: 0 | J3: 0 | K3: 13.91 | L3: 1 | M3: =VLOOKUP($E3,'only2-60'!$A$2:$H$848,5,0) -> #N/A | P3: =VLOOKUP(E3,'Take it'!$A$4:$D$771,2,0) -> 107.06
A4: ST00439/26 | B4: ST0043901N | C4: 46271 | D4: KIRAN INDUSTRIES PVT LTD (STICH DIV SALES) | E4: D10005 | F4: 13.91 | I4: 0 | J4: 0 | K4: 13.91 | M4: =VLOOKUP($E4,'only2-60'!$A$2:$H$848,5,0) -> #N/A | P4: =VLOOKUP(E4,'Take it'!$A$4:$D$771,2,0) -> 26.26
A5: ST00445/26 | B5: ST0044508N | C5: 46271 | D5: KIRAN INDUSTRIES PVT LTD (STICH DIV SALES) | E5: D10036 | F5: 13.91 | I5: 0 | J5: 0 | K5: 13.91 | L5: 1 | M5: =VLOOKUP($E5,'only2-60'!$A$2:$H$848,5,0) -> #N/A | P5: =VLOOKUP(E5,'Take it'!$A$4:$D$771,2,0) -> 38.38
A6: ST00319/26 | B6: ST0031907N | C6: 46232 | D6: KIRAN INDUSTRIES PVT LTD (STICH DIV SALES) | E6: D10038 | F6: 13.91 | I6: 0 | J6: 0 | K6: 13.91 | L6: 2 | M6: =VLOOKUP($E6,'only2-60'!$A$2:$H$848,5,0) -> #N/A | P6: =VLOOKUP(E6,'Take it'!$A$4:$D$771,2,0) -> 26.26
A7: ST00445/26 | B7: ST0044509N | C7: 46271 | D7: KIRAN INDUSTRIES PVT LTD (STICH DIV SALES) | E7: D10038 | F7: 13.91 | I7: 0 | J7: 0 | K7: 13.91 | M7: =VLOOKUP($E7,'only2-60'!$A$2:$H$848,5,0) -> #N/A | P7: =VLOOKUP(E7,'Take it'!$A$4:$D$771,2,0) -> 26.26
A8: ST00445/26 | B8: ST0044550N | C8: 46271 | D8: KIRAN INDUSTRIES PVT LTD (STICH DIV SALES) | E8: D10063 | F8: 13.91 | I8: 0 | J8: 0 | K8: 13.91 | M8: =VLOOKUP($E8,'only2-60'!$A$2:$H$848,5,0) -> #N/A | P8: =VLOOKUP(E8,'Take it'!$A$4:$D$771,2,0) -> 20.2
A9: ST00445/26 | B9: ST0044564N | C9: 46271 | D9: KIRAN INDUSTRIES PVT LTD (STICH DIV SALES) | E9: D10073 | F9: 13.91 | I9: 0 | J9: 0 | K9: 13.91 | M9: =VLOOKUP($E9,'only2-60'!$A$2:$H$848,5,0) -> #N/A | P9: =VLOOKUP(E9,'Take it'!$A$4:$D$771,2,0) -> 13.13
A10: ST00445/26 | B10: ST0044565N | C10: 46271 | D10: KIRAN INDUSTRIES PVT LTD (STICH DIV SALES) | E10: D10074 | F10: 13.91 | I10: 0 | J10: 0 | K10: 13.91 | M10: =VLOOKUP($E10,'only2-60'!$A$2:$H$848,5,0) -> #N/A | P10: =VLOOKUP(E10,'Take it'!$A$4:$D$771,2,0) -> 13.13
A11: ST00445/26 | B11: ST0044566N | C11: 46271 | D11: KIRAN INDUSTRIES PVT LTD (STICH DIV SALES) | E11: D10076 | F11: 13.91 | I11: 0 | J11: 0 | K11: 13.91 | M11: =VLOOKUP($E11,'only2-60'!$A$2:$H$848,5,0) -> #N/A | P11: =VLOOKUP(E11,'Take it'!$A$4:$D$771,2,0) -> 13.13
A12: ST00445/26 | B12: ST0044570N | C12: 46271 | D12: KIRAN INDUSTRIES PVT LTD (STICH DIV SALES) | E12: D10082 | F12: 13.91 | I12: 0 | J12: 0 | K12: 13.91 | M12: =VLOOKUP($E12,'only2-60'!$A$2:$H$848,5,0) -> #N/A | P12: =VLOOKUP(E12,'Take it'!$A$4:$D$771,2,0) -> 30.098
A13: ST00445/26 | B13: ST0044571N | C13: 46271 | D13: KIRAN INDUSTRIES PVT LTD (STICH DIV SALES) | E13: D10092 | F13: 13.91 | I13: 0 | J13: 0 | K13: 13.91 | M13: =VLOOKUP($E13,'only2-60'!$A$2:$H$848,5,0) -> #N/A | P13: =VLOOKUP(E13,'Take it'!$A$4:$D$771,2,0) -> 39.39
A14: ST00445/26 | B14: ST0044572N | C14: 46271 | D14: KIRAN INDUSTRIES PVT LTD (STICH DIV SALES) | E14: D10093 | F14: 13.91 | I14: 0 | J14: 0 | K14: 13.91 | M14: =VLOOKUP($E14,'only2-60'!$A$2:$H$848,5,0) -> #N/A | P14: =VLOOKUP(E14,'Take it'!$A$4:$D$771,2,0) -> 26.26
A15: ST00445/26 | B15: ST0044573N | C15: 46271 | D15: KIRAN INDUSTRIES PVT LTD (STICH DIV SALES) | E15: D10098 | F15: 13.91 | I15: 0 | J15: 0 | K15: 13.91 | M15: =VLOOKUP($E15,'only2-60'!$A$2:$H$848,5,0) -> #N/A | P15: =VLOOKUP(E15,'Take it'!$A$4:$D$771,2,0) -> 25.856
A16: ST00445/26 | B16: ST0044574N | C16: 46271 | D16: KIRAN INDUSTRIES PVT LTD (STICH DIV SALES) | E16: D10101 | F16: 13.91 | I16: 0 | J16: 0 | K16: 13.91 | M16: =VLOOKUP($E16,'only2-60'!$A$2:$H$848,5,0) -> #N/A | P16: =VLOOKUP(E16,'Take it'!$A$4:$D$771,2,0) -> 26.26
A17: ST00445/26 | B17: ST0044575N | C17: 46271 | D17: KIRAN INDUSTRIES PVT LTD (STICH DIV SALES) | E17: D10102 | F17: 13.91 | I17: 0 | J17: 0 | K17: 13.91 | M17: =VLOOKUP($E17,'only2-60'!$A$2:$H$848,5,0) -> #N/A | P17: =VLOOKUP(E17,'Take it'!$A$4:$D$771,2,0) -> 26.26
A18: ST00445/26 | B18: ST0044576N | C18: 46271 | D18: KIRAN INDUSTRIES PVT LTD (STICH DIV SALES) | E18: D10104 | F18: 13.91 | I18: 0 | J18: 0 | K18: 13.91 | M18: =VLOOKUP($E18,'only2-60'!$A$2:$H$848,5,0) -> #N/A | P18: =VLOOKUP(E18,'Take it'!$A$4:$D$771,2,0) -> 26.26
... A21: ST00445/26 | B21: ST0044579N | C21: 46271 | D21: KIRAN INDUSTRIES PVT LTD (STICH DIV SALES) | E21: D10114 | F21: 13.91 | I21: 0 | J21: 0 | K21: 13.91 | M21: =VLOOKUP($E21,'only2-60'!$A$2:$H$848,5,0) -> #N/A | P21: =VLOOKUP(E21,'Take it'!$A$4:$D$771,2,0) -> 66.458
A22: ST00231/26 | B22: ST0023101N | C22: 46200 | D22: KIRAN INDUSTRIES PVT LTD (STICH DIV SALES) | E22: KS-BLACK | F22: 1005.8 | G22: 111.28 | H22: 527.49 | I22: 0 | J22: 204.34 | K22: 367.03 | M22: =VLOOKUP($E22,'only2-60'!$A$2:$H$848,5,0) -> #N/A | P22: =VLOOKUP(E22,'Take it'!$A$4:$D$771,2,0) -> 8054.2131
A23: ST00445/26 | B23: ST0044580N | C23: 46271 | D23: KIRAN INDUSTRIES PVT LTD (STICH DIV SALES) | E23: LP111 | F23: 13.91 | I23: 0 | J23: 0 | K23: 13.91 | M23: =VLOOKUP($E23,'only2-60'!$A$2:$H$848,5,0) -> #N/A | P23: =VLOOKUP(E23,'Take it'!$A$4:$D$771,2,0) -> 13.13
A24: ST00449/26 | B24: ST0044901N | C24: 46273 | D24: KIRAN INDUSTRIES PVT LTD (STICH DIV SALES) | E24: NG308 | F24: 13.91 | I24: 0 | J24: 0 | K24: 13.91 | M24: =VLOOKUP($E24,'only2-60'!$A$2:$H$848,5,0) -> #N/A | P24: =VLOOKUP(E24,'Take it'!$A$4:$D$771,2,0) -> #N/A
A25: ST00439/26 | B25: ST0043938N | C25: 46271 | D25: KIRAN INDUSTRIES PVT LTD (STICH DIV SALES) | E25: QL103 | F25: 27.82 | I25: 0 | J25: 0 | K25: 27.82 | M25: =VLOOKUP($E25,'only2-60'!$A$2:$H$848,5,0) -> #N/A | P25: =VLOOKUP(E25,'Take it'!$A$4:$D$771,2,0) -> 72.72
A26: ST00439/26 | B26: ST0043923N | C26: 46271 | D26: KIRAN INDUSTRIES PVT LTD (STICH DIV SALES) | E26: R0120 | F26: 27.82 | I26: 0 | J26: 0 | K26: 27.82 | M26: =VLOOKUP($E26,'only2-60'!$A$2:$H$848,5,0) -> #N/A | P26: =VLOOKUP(E26,'Take it'!$A$4:$D$771,2,0) -> 33.33
A27: ST00445/26 | B27: ST0044513N | C27: 46271 | D27: KIRAN INDUSTRIES PVT LTD (STICH DIV SALES) | E27: S00026 | F27: 13.91 | I27: 0 | J27: 0 | K27: 13.91 | M27: =VLOOKUP($E27,'only2-60'!$A$2:$H$848,5,0) -> #N/A | P27: =VLOOKUP(E27,'Take it'!$A$4:$D$771,2,0) -> 13.13
A28: ST00439/26 | B28: ST0043908N | C28: 46271 | D28: KIRAN INDUSTRIES PVT LTD (STICH DIV SALES) | E28: S00052 | F28: 27.82 | I28: 0 | J28: 0 | K28: 27.82 | M28: =VLOOKUP($E28,'only2-60'!$A$2:$H$848,5,0) -> #N/A | P28: =VLOOKUP(E28,'Take it'!$A$4:$D$771,2,0) -> 26.26
A29: ST00445/26 | B29: ST0044514N | C29: 46271 | D29: KIRAN INDUSTRIES PVT LTD (STICH DIV SALES) | E29: S00082 | F29: 13.91 | I29: 0 | J29: 0 | K29: 13.91 | M29: =VLOOKUP($E29,'only2-60'!$A$2:$H$848,5,0) -> #N/A | P29: =VLOOKUP(E29,'Take it'!$A$4:$D$771,2,0) -> 39.39
A30: ST00445/26 | B30: ST0044512N | C30: 46271 | D30: KIRAN INDUSTRIES PVT LTD (STICH DIV SALES) | E30: S00103 | F30: 27.82 | I30: 0 | J30: 0 | K30: 27.82 | M30: =VLOOKUP($E30,'only2-60'!$A$2:$H$848,5,0) -> #N/A | P30: =VLOOKUP(E30,'Take it'!$A$4:$D$771,2,0) -> 58.895726
A31: ST00439/26 | B31: ST0043924N | C31: 46271 | D31: KIRAN INDUSTRIES PVT LTD (STICH DIV SALES) | E31: S00170 | F31: 81.32 | H31: 68.52 | I31: 0 | J31: 0 | K31: 12.8 | M31: =VLOOKUP($E31,'only2-60'!$A$2:$H$848,5,0) -> #N/A | P31: =VLOOKUP(E31,'Take it'!$A$4:$D$771,2,0) -> 288.86
A32: ST00445/26 | B32: ST0044511N | C32: 46271 | D32: KIRAN INDUSTRIES PVT LTD (STICH DIV SALES) | E32: S00272 | F32: 55.64 | I32: 0 | J32: 0 | K32: 55.64 | M32: =VLOOKUP($E32,'only2-60'!$A$2:$H$848,5,0) -> #N/A | P32: =VLOOKUP(E32,'Take it'!$A$4:$D$771,2,0) -> 78.78
A33: ST00439/26 | B33: ST0043948N | C33: 46271 | D33: KIRAN INDUSTRIES PVT LTD (STICH DIV SALES) | E33: S00308 | F33: 13.91 | I33: 0 | J33: 0 | K33: 13.91 | M33: =VLOOKUP($E33,'only2-60'!$A$2:$H$848,5,0) -> #N/A | P33: =VLOOKUP(E33,'Take it'!$A$4:$D$771,2,0) -> 13.13
A34: ST00439/26 | B34: ST0043934N | C34: 46271 | D34: KIRAN INDUSTRIES PVT LTD (STICH DIV SALES) | E34: S00445 | F34: 27.82 | I34: 0 | J34: 0 | K34: 27.82 | M34: =VLOOKUP($E34,'only2-60'!$A$2:$H$848,5,0) -> #N/A | P34: =VLOOKUP(E34,'Take it'!$A$4:$D$771,2,0) -> 26.26
A35: ST00439/26 | B35: ST0043935N | C35: 46271 | D35: KIRAN INDUSTRIES PVT LTD (STICH DIV SALES) | E35: S00462 | F35: 13.91 | I35: 0 | J35: 0 | K35: 13.91 | M35: =VLOOKUP($E35,'only2-60'!$A$2:$H$848,5,0) -> #N/A | P35: =VLOOKUP(E35,'Take it'!$A$4:$D$771,2,0) -> 13.13
A36: ST00439/26 | B36: ST0043941N | C36: 46271 | D36: KIRAN INDUSTRIES PVT LTD (STICH DIV SALES) | E36: S00608 | F36: 13.91 | I36: 0 | J36: 0 | K36: 13.91 | M36: =VLOOKUP($E36,'only2-60'!$A$2:$H$848,5,0) -> #N/A | P36: =VLOOKUP(E36,'Take it'!$A$4:$D$771,2,0) -> 13.13
A37: ST00445/26 | B37: ST0044559N | C37: 46271 | D37: KIRAN INDUSTRIES PVT LTD (STICH DIV SALES) | E37: S00635 | F37: 13.91 | I37: 0 | J37: 0 | K37: 13.91 | M37: =VLOOKUP($E37,'only2-60'!$A$2:$H$848,5,0) -> #N/A | P37: =VLOOKUP(E37,'Take it'!$A$4:$D$771,2,0) -> 33.33
A38: ST00439/26 | B38: ST0043906N | C38: 46271 | D38: KIRAN INDUSTRIES PVT LTD (STICH DIV SALES) | E38: S00651 | F38: 13.91 | I38: 0 | J38: 0 | K38: 13.91 | M38: =VLOOKUP($E38,'only2-60'!$A$2:$H$848,5,0) -> #N/A | P38: =VLOOKUP(E38,'Take it'!$A$4:$D$771,2,0) -> 190.89
A39: ST00442/26 | B39: ST0044205N | C39: 46271 | D39: KIRAN INDUSTRIES PVT LTD (STICH DIV SALES) | E39: S01000 | F39: 27.82 | I39: 0 | J39: 0 | K39: 27.82 | M39: =VLOOKUP($E39,'only2-60'!$A$2:$H$848,5,0) -> #N/A | P39: =VLOOKUP(E39,'Take it'!$A$4:$D$771,2,0) -> 26.26
A40: ST00445/26 | B40: ST0044510N | C40: 46271 | D40: KIRAN INDUSTRIES PVT LTD (STICH DIV SALES) | E40: S01028 | F40: 77.04 | I40: 0 | J40: 0 | K40: 77.04 | M40: =VLOOKUP($E40,'only2-60'!$A$2:$H$848,5,0) -> #N/A | P40: =VLOOKUP(E40,'Take it'!$A$4:$D$771,2,0) -> 206.87386
A41: ST00439/26 | B41: ST0043942N | C41: 46271 | D41: KIRAN INDUSTRIES PVT LTD (STICH DIV SALES) | E41: S01158 | F41: 27.82 | I41: 0 | J41: 0 | K41: 27.82 | M41: =VLOOKUP($E41,'only2-60'!$A$2:$H$848,5,0) -> #N/A | P41: =VLOOKUP(E41,'Take it'!$A$4:$D$771,2,0) -> 26.26
A42: ST00445/26 | B42: ST0044534N | C42: 46271 | D42: KIRAN INDUSTRIES PVT LTD (STICH DIV SALES) | E42: S01465 | F42: 27.82 | I42: 0 | J42: 0 | K42: 27.82 | M42: =VLOOKUP($E42,'only2-60'!$A$2:$H$848,5,0) -> #N/A | P42: =VLOOKUP(E42,'Take it'!$A$4:$D$771,2,0) -> 52.52
...

Sheet only2-60
A1: Article | B1: Color | C1: Last_date_of_Odr | D1: actual_tot_in_Qty | E1: actual_tot_wt_in_KG | F1: Total_Frequency | G1: No_of_parties | H1: Parties
A2: 1201 | B2: KS-BLACK | C2: 46258 | D2: 3890 | E2: 785.78 | F2: 12 | G2: 2 | H2: CHIRAG CREATIONS, ZIGMA
A3: 1201 | B3: BW | C3: 46158 | D3: 1130 | E3: 228.26 | F3: 4 | G3: 1 | H3: ZIGMA
A4: 1201 | B4: D10002 | C4: 46271 | D4: 65 | E4: 13.13 | F4: 1 | G4: 1 | H4: ZIGMA
A5: 1201 | B5: D10003 | C5: 46271 | D5: 530 | E5: 107.06 | F5: 5 | G5: 1 | H5: ZIGMA
A6: 1201 | B6: D10005 | C6: 46270 | D6: 130 | E6: 26.26 | F6: 2 | G6: 1 | H6: ZIGMA
A7: 1201 | B7: D10006 | C7: 46193 | D7: 100 | E7: 20.2 | F7: 2 | G7: 1 | H7: ZIGMA
A8: 1201 | B8: D10007 | C8: 46192 | D8: 120 | E8: 24.24 | F8: 2 | G8: 1 | H8: ZIGMA
A9: 1201 | B9: D10008 | C9: 46195 | D9: 100 | E9: 20.2 | F9: 1 | G9: 1 | H9: ZIGMA
A10: 1201 | B10: D10011 | C10: 46233 | D10: 255 | E10: 51.51 | F10: 6 | G10: 2 | H10: K.K. HOSIERY MATERIAL STORE, ZIGMA
A11: 1201 | B11: D10033 | C11: 46164 | D11: 190 | E11: 38.38 | F11: 1 | G11: 1 | H11: ZIGMA
A12: 1201 | B12: D10035 | C12: 46265 | D12: 70 | E12: 14.14 | F12: 3 | G12: 1 | H12: ZIGMA
A13: 1201 | B13: D10036 | C13: 46271 | D13: 190 | E13: 38.38 | F13: 4 | G13: 1 | H13: ZIGMA
... A848: 1211 | B848: SV6103 | C848: 46197 | D848: 0 | E848: 0 | F848: 1 | G848: 1 | H848: ZIGMA

Sheet Take it
A3: Row Labels | B3: Sum of actual_tot_wt_in_KG | C3: Sum of Total_Frequency | D3: Sum of No_of_parties
A4: BW | B4: 228.26 | C4: 4 | D4: 1
A5: D10002 | B5: 13.13 | C5: 1 | D5: 1
A6: D10003 | B6: 107.06 | C6: 5 | D6: 1
A7: D10005 | B7: 26.26 | C7: 2 | D7: 1
A8: D10006 | B8: 20.2 | C8: 2 | D8: 1
A9: D10007 | B9: 24.24 | C9: 2 | D9: 1
A10: D10008 | B10: 20.2 | C10: 1 | D10: 1
A11: D10011 | B11: 51.51 | C11: 6 | D11: 2
A12: D10033 | B12: 38.38 | C12: 1 | D12: 1
A13: D10035 | B13: 14.14 | C13: 3 | D13: 1
A14: D10036 | B14: 38.38 | C14: 4 | D14: 1
A15: D10037 | B15: 31.31 | C15: 4 | D15: 1
... A772: Grand Total | B772: 75955.643 | C772: 3759 | D772: 880
